2020-12-03 15:05:08,745 - ERROR - publicLog.py[:58]- Traceback (most recent call last):
  File "E:\python_project\lhwms\log\views\errlog.py", line 35, in search_data
    data = data_search.data_search(request, model, query_mark=query_mark,)
  File "E:\python_project\lhwms\lhwms\utils\data_search.py", line 37, in data_search
    rc_search_result.set(rc_key, json.dumps(list(data)),
  File "e:\python\lib\json\__init__.py", line 231, in dumps
    return _default_encoder.encode(obj)
  File "e:\python\lib\json\encoder.py", line 199, in encode
    chunks = self.iterencode(o, _one_shot=True)
  File "e:\python\lib\json\encoder.py", line 257, in iterencode
    return _iterencode(o, 0)
  File "e:\python\lib\json\encoder.py", line 179, in default
    raise TypeError(f'Object of type {o.__class__.__name__} '
TypeError: Object of type datetime is not JSON serializable

2020-12-03 15:07:54,615 - ERROR - publicLog.py[:58]- Traceback (most recent call last):
  File "E:\python_project\lhwms\log\views\errlog.py", line 35, in search_data
    data = data_search.data_search(request, model, query_mark=query_mark,)
  File "E:\python_project\lhwms\lhwms\utils\data_search.py", line 37, in data_search
    rc_search_result.set(rc_key, json.dumps(list(data)),
  File "e:\python\lib\json\__init__.py", line 231, in dumps
    return _default_encoder.encode(obj)
  File "e:\python\lib\json\encoder.py", line 199, in encode
    chunks = self.iterencode(o, _one_shot=True)
  File "e:\python\lib\json\encoder.py", line 257, in iterencode
    return _iterencode(o, 0)
  File "e:\python\lib\json\encoder.py", line 179, in default
    raise TypeError(f'Object of type {o.__class__.__name__} '
TypeError: Object of type datetime is not JSON serializable

2020-12-03 15:17:15,529 - ERROR - publicLog.py[:58]- Traceback (most recent call last):
  File "E:\python_project\lhwms\log\views\errlog.py", line 37, in search_data
    data = data_search.data_search(request, model, query_mark=query_mark,)
  File "E:\python_project\lhwms\lhwms\utils\data_search.py", line 37, in data_search
    rc_search_result.set(rc_key, json.dumps(list(data)),
  File "e:\python\lib\json\__init__.py", line 231, in dumps
    return _default_encoder.encode(obj)
  File "e:\python\lib\json\encoder.py", line 199, in encode
    chunks = self.iterencode(o, _one_shot=True)
  File "e:\python\lib\json\encoder.py", line 257, in iterencode
    return _iterencode(o, 0)
  File "e:\python\lib\json\encoder.py", line 179, in default
    raise TypeError(f'Object of type {o.__class__.__name__} '
TypeError: Object of type datetime is not JSON serializable

2020-12-03 15:26:08,797 - ERROR - publicLog.py[:58]- Traceback (most recent call last):
  File "E:\python_project\lhwms\log\views\errlog.py", line 37, in search_data
    data = data_search.data_search(request, model, query_mark=query_mark,)
  File "E:\python_project\lhwms\lhwms\utils\data_search.py", line 35, in data_search
    rc_search_result.set(rc_key, json.dumps(list(data)),
  File "e:\python\lib\json\__init__.py", line 231, in dumps
    return _default_encoder.encode(obj)
  File "e:\python\lib\json\encoder.py", line 199, in encode
    chunks = self.iterencode(o, _one_shot=True)
  File "e:\python\lib\json\encoder.py", line 257, in iterencode
    return _iterencode(o, 0)
  File "e:\python\lib\json\encoder.py", line 179, in default
    raise TypeError(f'Object of type {o.__class__.__name__} '
TypeError: Object of type datetime is not JSON serializable

2020-12-03 15:26:10,638 - ERROR - publicLog.py[:58]- Traceback (most recent call last):
  File "E:\python_project\lhwms\log\views\errlog.py", line 37, in search_data
    data = data_search.data_search(request, model, query_mark=query_mark,)
  File "E:\python_project\lhwms\lhwms\utils\data_search.py", line 35, in data_search
    rc_search_result.set(rc_key, json.dumps(list(data)),
  File "e:\python\lib\json\__init__.py", line 231, in dumps
    return _default_encoder.encode(obj)
  File "e:\python\lib\json\encoder.py", line 199, in encode
    chunks = self.iterencode(o, _one_shot=True)
  File "e:\python\lib\json\encoder.py", line 257, in iterencode
    return _iterencode(o, 0)
  File "e:\python\lib\json\encoder.py", line 179, in default
    raise TypeError(f'Object of type {o.__class__.__name__} '
TypeError: Object of type datetime is not JSON serializable

2020-12-03 16:01:02,767 - ERROR - publicLog.py[:58]- Traceback (most recent call last):
  File "E:\python_project\lhwms\log\views\errlog.py", line 34, in search_data
    terms = json.loads(request.POST.get('terms'))
  File "e:\python\lib\json\__init__.py", line 341, in loads
    raise TypeError(f'the JSON object must be str, bytes or bytearray, '
TypeError: the JSON object must be str, bytes or bytearray, not NoneType

2020-12-03 17:40:33,926 - WARNING - publicLog.py[:56]- Traceback (most recent call last):
  File "E:\envs\shennaji_work1\lib\site-packages\django\utils\datastructures.py", line 83, in __getitem__
    list_ = super(MultiValueDict, self).__getitem__(key)
KeyError: 'page'

During handling of the above exception, another exception occurred:

Traceback (most recent call last):
  File "E:\python_project\lhwms\lhwms\utils\data_search.py", line 52, in data_paginator
    if request.GET['page'] is not None:
  File "E:\envs\shennaji_work1\lib\site-packages\django\utils\datastructures.py", line 85, in __getitem__
    raise MultiValueDictKeyError(repr(key))
django.utils.datastructures.MultiValueDictKeyError: "'page'"

2020-12-03 17:40:33,930 - ERROR - publicLog.py[:58]- Traceback (most recent call last):
  File "E:\python_project\lhwms\log\views\errlog.py", line 40, in search_data
  File "E:\python_project\lhwms\lhwms\utils\restful.py", line 22, in ok
    return result(message=message, data=data)
  File "E:\python_project\lhwms\lhwms\utils\restful.py", line 18, in result
    return JsonResponse(json_data)
  File "E:\envs\shennaji_work1\lib\site-packages\django\http\response.py", line 530, in __init__
    data = json.dumps(data, cls=encoder, **json_dumps_params)
  File "e:\python\lib\json\__init__.py", line 238, in dumps
    **kw).encode(obj)
  File "e:\python\lib\json\encoder.py", line 199, in encode
    chunks = self.iterencode(o, _one_shot=True)
  File "e:\python\lib\json\encoder.py", line 257, in iterencode
    return _iterencode(o, 0)
  File "E:\envs\shennaji_work1\lib\site-packages\django\core\serializers\json.py", line 124, in default
    return super(DjangoJSONEncoder, self).default(o)
  File "e:\python\lib\json\encoder.py", line 179, in default
    raise TypeError(f'Object of type {o.__class__.__name__} '
TypeError: Object of type JsonResponse is not JSON serializable

2020-12-03 17:44:44,099 - WARNING - publicLog.py[:56]- Traceback (most recent call last):
  File "E:\envs\shennaji_work1\lib\site-packages\django\utils\datastructures.py", line 83, in __getitem__
    list_ = super(MultiValueDict, self).__getitem__(key)
KeyError: 'page'

During handling of the above exception, another exception occurred:

Traceback (most recent call last):
  File "E:\python_project\lhwms\lhwms\utils\data_search.py", line 52, in data_paginator
    if request.GET['page'] is not None:
  File "E:\envs\shennaji_work1\lib\site-packages\django\utils\datastructures.py", line 85, in __getitem__
    raise MultiValueDictKeyError(repr(key))
django.utils.datastructures.MultiValueDictKeyError: "'page'"

2020-12-03 17:44:44,100 - ERROR - publicLog.py[:58]- Traceback (most recent call last):
  File "E:\python_project\lhwms\log\views\errlog.py", line 40, in search_data
  File "E:\python_project\lhwms\lhwms\utils\restful.py", line 22, in ok
    return result(message=message, data=data)
  File "E:\python_project\lhwms\lhwms\utils\restful.py", line 18, in result
    return JsonResponse(json_data)
  File "E:\envs\shennaji_work1\lib\site-packages\django\http\response.py", line 530, in __init__
    data = json.dumps(data, cls=encoder, **json_dumps_params)
  File "e:\python\lib\json\__init__.py", line 238, in dumps
    **kw).encode(obj)
  File "e:\python\lib\json\encoder.py", line 199, in encode
    chunks = self.iterencode(o, _one_shot=True)
  File "e:\python\lib\json\encoder.py", line 257, in iterencode
    return _iterencode(o, 0)
  File "E:\envs\shennaji_work1\lib\site-packages\django\core\serializers\json.py", line 124, in default
    return super(DjangoJSONEncoder, self).default(o)
  File "e:\python\lib\json\encoder.py", line 179, in default
    raise TypeError(f'Object of type {o.__class__.__name__} '
TypeError: Object of type JsonResponse is not JSON serializable

2020-12-03 17:44:51,286 - WARNING - publicLog.py[:56]- Traceback (most recent call last):
  File "E:\envs\shennaji_work1\lib\site-packages\django\utils\datastructures.py", line 83, in __getitem__
    list_ = super(MultiValueDict, self).__getitem__(key)
KeyError: 'page'

During handling of the above exception, another exception occurred:

Traceback (most recent call last):
  File "E:\python_project\lhwms\lhwms\utils\data_search.py", line 52, in data_paginator
    if request.GET['page'] is not None:
  File "E:\envs\shennaji_work1\lib\site-packages\django\utils\datastructures.py", line 85, in __getitem__
    raise MultiValueDictKeyError(repr(key))
django.utils.datastructures.MultiValueDictKeyError: "'page'"

2020-12-03 17:47:39,293 - WARNING - publicLog.py[:56]- Traceback (most recent call last):
  File "E:\envs\shennaji_work1\lib\site-packages\django\utils\datastructures.py", line 83, in __getitem__
    list_ = super(MultiValueDict, self).__getitem__(key)
KeyError: 'page'

During handling of the above exception, another exception occurred:

Traceback (most recent call last):
  File "E:\python_project\lhwms\lhwms\utils\data_search.py", line 52, in data_paginator
    if request.GET['page'] is not None:
  File "E:\envs\shennaji_work1\lib\site-packages\django\utils\datastructures.py", line 85, in __getitem__
    raise MultiValueDictKeyError(repr(key))
django.utils.datastructures.MultiValueDictKeyError: "'page'"

2020-12-03 17:48:17,592 - WARNING - publicLog.py[:56]- Traceback (most recent call last):
  File "E:\envs\shennaji_work1\lib\site-packages\django\utils\datastructures.py", line 83, in __getitem__
    list_ = super(MultiValueDict, self).__getitem__(key)
KeyError: 'page'

During handling of the above exception, another exception occurred:

Traceback (most recent call last):
  File "E:\python_project\lhwms\lhwms\utils\data_search.py", line 52, in data_paginator
    if request.GET['page'] is not None:
  File "E:\envs\shennaji_work1\lib\site-packages\django\utils\datastructures.py", line 85, in __getitem__
    raise MultiValueDictKeyError(repr(key))
django.utils.datastructures.MultiValueDictKeyError: "'page'"

2020-12-03 17:52:11,969 - WARNING - publicLog.py[:56]- Traceback (most recent call last):
  File "E:\envs\shennaji_work1\lib\site-packages\django\utils\datastructures.py", line 83, in __getitem__
    list_ = super(MultiValueDict, self).__getitem__(key)
KeyError: 'page'

During handling of the above exception, another exception occurred:

Traceback (most recent call last):
  File "E:\python_project\lhwms\lhwms\utils\data_search.py", line 52, in data_paginator
    if request.GET['page'] is not None:
  File "E:\envs\shennaji_work1\lib\site-packages\django\utils\datastructures.py", line 85, in __getitem__
    raise MultiValueDictKeyError(repr(key))
django.utils.datastructures.MultiValueDictKeyError: "'page'"

2020-12-03 17:52:23,609 - WARNING - publicLog.py[:56]- Traceback (most recent call last):
  File "E:\envs\shennaji_work1\lib\site-packages\django\utils\datastructures.py", line 83, in __getitem__
    list_ = super(MultiValueDict, self).__getitem__(key)
KeyError: 'page'

During handling of the above exception, another exception occurred:

Traceback (most recent call last):
  File "E:\python_project\lhwms\lhwms\utils\data_search.py", line 52, in data_paginator
    if request.GET['page'] is not None:
  File "E:\envs\shennaji_work1\lib\site-packages\django\utils\datastructures.py", line 85, in __getitem__
    raise MultiValueDictKeyError(repr(key))
django.utils.datastructures.MultiValueDictKeyError: "'page'"

2020-12-03 17:52:25,180 - WARNING - publicLog.py[:56]- Traceback (most recent call last):
  File "E:\envs\shennaji_work1\lib\site-packages\django\utils\datastructures.py", line 83, in __getitem__
    list_ = super(MultiValueDict, self).__getitem__(key)
KeyError: 'page'

During handling of the above exception, another exception occurred:

Traceback (most recent call last):
  File "E:\python_project\lhwms\lhwms\utils\data_search.py", line 52, in data_paginator
    if request.GET['page'] is not None:
  File "E:\envs\shennaji_work1\lib\site-packages\django\utils\datastructures.py", line 85, in __getitem__
    raise MultiValueDictKeyError(repr(key))
django.utils.datastructures.MultiValueDictKeyError: "'page'"

2020-12-03 17:52:25,690 - WARNING - publicLog.py[:56]- Traceback (most recent call last):
  File "E:\envs\shennaji_work1\lib\site-packages\django\utils\datastructures.py", line 83, in __getitem__
    list_ = super(MultiValueDict, self).__getitem__(key)
KeyError: 'page'

During handling of the above exception, another exception occurred:

Traceback (most recent call last):
  File "E:\python_project\lhwms\lhwms\utils\data_search.py", line 52, in data_paginator
    if request.GET['page'] is not None:
  File "E:\envs\shennaji_work1\lib\site-packages\django\utils\datastructures.py", line 85, in __getitem__
    raise MultiValueDictKeyError(repr(key))
django.utils.datastructures.MultiValueDictKeyError: "'page'"

2020-12-03 17:52:26,239 - WARNING - publicLog.py[:56]- Traceback (most recent call last):
  File "E:\envs\shennaji_work1\lib\site-packages\django\utils\datastructures.py", line 83, in __getitem__
    list_ = super(MultiValueDict, self).__getitem__(key)
KeyError: 'page'

During handling of the above exception, another exception occurred:

Traceback (most recent call last):
  File "E:\python_project\lhwms\lhwms\utils\data_search.py", line 52, in data_paginator
    if request.GET['page'] is not None:
  File "E:\envs\shennaji_work1\lib\site-packages\django\utils\datastructures.py", line 85, in __getitem__
    raise MultiValueDictKeyError(repr(key))
django.utils.datastructures.MultiValueDictKeyError: "'page'"

2020-12-03 17:53:51,482 - WARNING - publicLog.py[:56]- Traceback (most recent call last):
  File "E:\envs\shennaji_work1\lib\site-packages\django\utils\datastructures.py", line 83, in __getitem__
    list_ = super(MultiValueDict, self).__getitem__(key)
KeyError: 'page'

During handling of the above exception, another exception occurred:

Traceback (most recent call last):
  File "E:\python_project\lhwms\lhwms\utils\data_search.py", line 52, in data_paginator
    if request.GET['page'] is not None:
  File "E:\envs\shennaji_work1\lib\site-packages\django\utils\datastructures.py", line 85, in __getitem__
    raise MultiValueDictKeyError(repr(key))
django.utils.datastructures.MultiValueDictKeyError: "'page'"

2020-12-03 18:05:48,170 - WARNING - publicLog.py[:56]- Traceback (most recent call last):
  File "E:\python_project\lhwms\lhwms\utils\data_search.py", line 72, in data_paginator
    current_page_data = paginator.page(page)  # 获取当前页数据对象
  File "E:\envs\shennaji_work1\lib\site-packages\django\core\paginator.py", line 57, in page
    number = self.validate_number(number)
  File "E:\envs\shennaji_work1\lib\site-packages\django\core\paginator.py", line 50, in validate_number
    raise EmptyPage(_('That page contains no results'))
django.core.paginator.EmptyPage: 本页结果未空

2020-12-03 18:06:48,197 - WARNING - publicLog.py[:56]- Traceback (most recent call last):
  File "E:\python_project\lhwms\lhwms\utils\data_search.py", line 72, in data_paginator
    current_page_data = paginator.page(page)  # 获取当前页数据对象
  File "E:\envs\shennaji_work1\lib\site-packages\django\core\paginator.py", line 57, in page
    number = self.validate_number(number)
  File "E:\envs\shennaji_work1\lib\site-packages\django\core\paginator.py", line 50, in validate_number
    raise EmptyPage(_('That page contains no results'))
django.core.paginator.EmptyPage: 本页结果未空

2020-12-03 18:08:27,116 - WARNING - publicLog.py[:56]- Traceback (most recent call last):
  File "E:\python_project\lhwms\lhwms\utils\data_search.py", line 72, in data_paginator
    current_page_data = paginator.page(page)  # 获取当前页数据对象
  File "E:\envs\shennaji_work1\lib\site-packages\django\core\paginator.py", line 57, in page
    number = self.validate_number(number)
  File "E:\envs\shennaji_work1\lib\site-packages\django\core\paginator.py", line 50, in validate_number
    raise EmptyPage(_('That page contains no results'))
django.core.paginator.EmptyPage: 本页结果未空

2020-12-03 18:09:23,658 - WARNING - publicLog.py[:56]- Traceback (most recent call last):
  File "E:\python_project\lhwms\lhwms\utils\data_search.py", line 72, in data_paginator
    current_page_data = paginator.page(page)  # 获取当前页数据对象
  File "E:\envs\shennaji_work1\lib\site-packages\django\core\paginator.py", line 57, in page
    number = self.validate_number(number)
  File "E:\envs\shennaji_work1\lib\site-packages\django\core\paginator.py", line 50, in validate_number
    raise EmptyPage(_('That page contains no results'))
django.core.paginator.EmptyPage: 本页结果未空

2020-12-03 18:10:05,902 - WARNING - publicLog.py[:56]- Traceback (most recent call last):
  File "E:\python_project\lhwms\lhwms\utils\data_search.py", line 72, in data_paginator
    current_page_data = paginator.page(page)  # 获取当前页数据对象
  File "E:\envs\shennaji_work1\lib\site-packages\django\core\paginator.py", line 57, in page
    number = self.validate_number(number)
  File "E:\envs\shennaji_work1\lib\site-packages\django\core\paginator.py", line 50, in validate_number
    raise EmptyPage(_('That page contains no results'))
django.core.paginator.EmptyPage: 本页结果未空

2020-12-03 18:10:06,726 - WARNING - publicLog.py[:56]- Traceback (most recent call last):
  File "E:\python_project\lhwms\lhwms\utils\data_search.py", line 72, in data_paginator
    current_page_data = paginator.page(page)  # 获取当前页数据对象
  File "E:\envs\shennaji_work1\lib\site-packages\django\core\paginator.py", line 57, in page
    number = self.validate_number(number)
  File "E:\envs\shennaji_work1\lib\site-packages\django\core\paginator.py", line 50, in validate_number
    raise EmptyPage(_('That page contains no results'))
django.core.paginator.EmptyPage: 本页结果未空

2020-12-03 18:10:07,460 - WARNING - publicLog.py[:56]- Traceback (most recent call last):
  File "E:\python_project\lhwms\lhwms\utils\data_search.py", line 72, in data_paginator
    current_page_data = paginator.page(page)  # 获取当前页数据对象
  File "E:\envs\shennaji_work1\lib\site-packages\django\core\paginator.py", line 57, in page
    number = self.validate_number(number)
  File "E:\envs\shennaji_work1\lib\site-packages\django\core\paginator.py", line 50, in validate_number
    raise EmptyPage(_('That page contains no results'))
django.core.paginator.EmptyPage: 本页结果未空

2020-12-03 18:10:42,109 - WARNING - publicLog.py[:56]- Traceback (most recent call last):
  File "E:\python_project\lhwms\lhwms\utils\data_search.py", line 72, in data_paginator
    current_page_data = paginator.page(page)  # 获取当前页数据对象
  File "E:\envs\shennaji_work1\lib\site-packages\django\core\paginator.py", line 57, in page
    number = self.validate_number(number)
  File "E:\envs\shennaji_work1\lib\site-packages\django\core\paginator.py", line 50, in validate_number
    raise EmptyPage(_('That page contains no results'))
django.core.paginator.EmptyPage: 本页结果未空

2020-12-03 18:10:44,370 - WARNING - publicLog.py[:56]- Traceback (most recent call last):
  File "E:\python_project\lhwms\lhwms\utils\data_search.py", line 72, in data_paginator
    current_page_data = paginator.page(page)  # 获取当前页数据对象
  File "E:\envs\shennaji_work1\lib\site-packages\django\core\paginator.py", line 57, in page
    number = self.validate_number(number)
  File "E:\envs\shennaji_work1\lib\site-packages\django\core\paginator.py", line 50, in validate_number
    raise EmptyPage(_('That page contains no results'))
django.core.paginator.EmptyPage: 本页结果未空

2020-12-03 18:10:45,450 - WARNING - publicLog.py[:56]- Traceback (most recent call last):
  File "E:\python_project\lhwms\lhwms\utils\data_search.py", line 72, in data_paginator
    current_page_data = paginator.page(page)  # 获取当前页数据对象
  File "E:\envs\shennaji_work1\lib\site-packages\django\core\paginator.py", line 57, in page
    number = self.validate_number(number)
  File "E:\envs\shennaji_work1\lib\site-packages\django\core\paginator.py", line 50, in validate_number
    raise EmptyPage(_('That page contains no results'))
django.core.paginator.EmptyPage: 本页结果未空

2020-12-03 18:11:04,448 - WARNING - publicLog.py[:56]- Traceback (most recent call last):
  File "E:\python_project\lhwms\lhwms\utils\data_search.py", line 72, in data_paginator
    current_page_data = paginator.page(page)  # 获取当前页数据对象
  File "E:\envs\shennaji_work1\lib\site-packages\django\core\paginator.py", line 57, in page
    number = self.validate_number(number)
  File "E:\envs\shennaji_work1\lib\site-packages\django\core\paginator.py", line 50, in validate_number
    raise EmptyPage(_('That page contains no results'))
django.core.paginator.EmptyPage: 本页结果未空

2020-12-03 18:13:45,399 - WARNING - publicLog.py[:56]- Traceback (most recent call last):
  File "E:\python_project\lhwms\lhwms\utils\data_search.py", line 72, in data_paginator
    current_page_data = paginator.page(page)  # 获取当前页数据对象
  File "E:\envs\shennaji_work1\lib\site-packages\django\core\paginator.py", line 57, in page
    number = self.validate_number(number)
  File "E:\envs\shennaji_work1\lib\site-packages\django\core\paginator.py", line 50, in validate_number
    raise EmptyPage(_('That page contains no results'))
django.core.paginator.EmptyPage: 本页结果未空

2020-12-03 18:14:52,455 - WARNING - publicLog.py[:56]- Traceback (most recent call last):
  File "E:\python_project\lhwms\lhwms\utils\data_search.py", line 72, in data_paginator
    current_page_data = paginator.page(page)  # 获取当前页数据对象
  File "E:\envs\shennaji_work1\lib\site-packages\django\core\paginator.py", line 57, in page
    number = self.validate_number(number)
  File "E:\envs\shennaji_work1\lib\site-packages\django\core\paginator.py", line 50, in validate_number
    raise EmptyPage(_('That page contains no results'))
django.core.paginator.EmptyPage: 本页结果未空

2020-12-03 18:17:01,065 - WARNING - publicLog.py[:56]- Traceback (most recent call last):
  File "E:\python_project\lhwms\lhwms\utils\data_search.py", line 72, in data_paginator
    current_page_data = paginator.page(page)  # 获取当前页数据对象
  File "E:\envs\shennaji_work1\lib\site-packages\django\core\paginator.py", line 57, in page
    number = self.validate_number(number)
  File "E:\envs\shennaji_work1\lib\site-packages\django\core\paginator.py", line 50, in validate_number
    raise EmptyPage(_('That page contains no results'))
django.core.paginator.EmptyPage: 本页结果未空

2020-12-03 18:27:30,738 - WARNING - publicLog.py[:56]- Traceback (most recent call last):
  File "E:\python_project\lhwms\lhwms\utils\data_search.py", line 72, in data_paginator
    current_page_data = paginator.page(page)  # 获取当前页数据对象
  File "E:\envs\shennaji_work1\lib\site-packages\django\core\paginator.py", line 57, in page
    number = self.validate_number(number)
  File "E:\envs\shennaji_work1\lib\site-packages\django\core\paginator.py", line 50, in validate_number
    raise EmptyPage(_('That page contains no results'))
django.core.paginator.EmptyPage: 本页结果未空

2020-12-03 18:27:31,693 - WARNING - publicLog.py[:56]- Traceback (most recent call last):
  File "E:\python_project\lhwms\lhwms\utils\data_search.py", line 72, in data_paginator
    current_page_data = paginator.page(page)  # 获取当前页数据对象
  File "E:\envs\shennaji_work1\lib\site-packages\django\core\paginator.py", line 57, in page
    number = self.validate_number(number)
  File "E:\envs\shennaji_work1\lib\site-packages\django\core\paginator.py", line 50, in validate_number
    raise EmptyPage(_('That page contains no results'))
django.core.paginator.EmptyPage: 本页结果未空

2020-12-03 18:42:12,171 - WARNING - publicLog.py[:56]- Traceback (most recent call last):
  File "E:\python_project\lhwms\lhwms\utils\data_search.py", line 74, in data_paginator
    current_page_data = paginator.page(page)  # 获取当前页数据对象
  File "E:\envs\shennaji_work1\lib\site-packages\django\core\paginator.py", line 57, in page
    number = self.validate_number(number)
  File "E:\envs\shennaji_work1\lib\site-packages\django\core\paginator.py", line 50, in validate_number
    raise EmptyPage(_('That page contains no results'))
django.core.paginator.EmptyPage: 本页结果未空

